<?xml version="1.0"?>
<robot name="manipulator">

  <!-- Link definitions -->
  <link name="frame_down_link">
    <visual>
      <geometry>
        <cylinder radius="0.05" length="0.5"/>
      </geometry>
      <material name="gray">
        <color rgba=".2 .2 .2 1" />
      </material>
    </visual>
    <inertial>
      <mass value="1" />
      <inertia ixx="0.01" ixy="0.0" ixz="0" iyy="0.01" iyz="0" izz="0.01" />
    </inertial>
    <collision>
      <geometry>
        <cylinder radius="0.05" length="0.5"/>
      </geometry>
    </collision>
  </link>

  <link name="frame_middle_link">
    <visual>
      <geometry>
        <cylinder radius="0.05" length="0.5"/>
      </geometry>
      <material name="gray">
        <color rgba=".2 .2 .2 1" />
      </material>
    </visual>
    <inertial>
      <mass value="1" />
      <inertia ixx="0.01" ixy="0.0" ixz="0" iyy="0.01" iyz="0" izz="0.01" />
    </inertial>
    <collision>
      <geometry>
        <cylinder radius="0.05" length="0.5"/>
      </geometry>
    </collision>
  </link>

  <link name="frame_up_link">
    <visual>
      <geometry>
        <cylinder radius="0.05" length="0.5"/>
      </geometry>
      <material name="gray">
        <color rgba=".2 .2 .2 1" />
      </material>
    </visual>
    <inertial>
      <mass value="1" />
      <inertia ixx="0.01" ixy="0.0" ixz="0" iyy="0.01" iyz="0" izz="0.01" />
    </inertial>
    <collision>
      <geometry>
        <cylinder radius="0.05" length="0.5"/>
      </geometry>
    </collision>
  </link>

  <link name="finger_link">
    <visual>
      <geometry>
        <cylinder radius="0.05" length="0.3"/>
      </geometry>
      <material name="gray">
        <color rgba=".2 .2 .2 1" />
      </material>
    </visual>
    <inertial>
      <mass value="1" />
      <inertia ixx="0.01" ixy="0.0" ixz="0" iyy="0.01" iyz="0" izz="0.01" />
    </inertial>
    <collision>
      <geometry>
        <cylinder radius="0.05" length="0.3"/>
      </geometry>
    </collision>
  </link>

  <link name="base">
    <visual>
      <geometry>
        <box size="0.75 0.4 0.1"/>
      </geometry>
      <material name="gray">
        <color rgba=".2 .2 .2 1" />
      </material>
    </visual>
    <inertial>
      <mass value="1" />
      <inertia ixx="0.01" ixy="0.0" ixz="0" iyy="0.01" iyz="0" izz="0.01" />
    </inertial>
    <collision>
      <geometry>
        <box size="0.75 0.4 0.1"/>
      </geometry>
    </collision>
  </link>
  


  <!-- Joints -->
  <joint name="frame_base_joint" type="fixed">
    <parent link="base"/>
    <child link="frame_down_link"/>
    <origin xyz="0.0 0.0 0.25" rpy="0.0 0.0 1.5"/>
    <axis xyz="0.0 0.0 1.0"/>
  </joint>

  <joint name="frame_down_joint" type="revolute">
    <parent link="frame_down_link"/>
    <child link="frame_middle_link"/>
    <origin xyz="0.1 0.0 0.25" rpy="-0.5 0.0 0.0"/>
    <axis xyz="1.0 0.0 0.0"/>
    <limit effort="10" velocity="1.0" lower="-1.0" upper="0.5" />
  </joint>

  <joint name="frame_middle_joint" type="revolute">
    <parent link="frame_middle_link"/>
    <child link="frame_up_link"/>
    <origin xyz="0.1 0.0 0.25" rpy="-0.5 0.0 0.0"/>
    <axis xyz="1.0 0.0 0.0"/>
    <limit effort="10" velocity="1.0" lower="-1.0" upper="0.5" />
  </joint>

   <joint name="finger_joint" type="prismatic">
    <parent link="frame_up_link"/>
    <child link="finger_link"/>
    <origin xyz="0.0 0.0 0.30" rpy="0.0 0.0 0.0"/>
    <axis xyz="0.0 0.0 1.0"/>
    <limit effort="10" velocity="1.0" lower="-0.2" upper="0.2" />
  </joint>
 

  <ros2_control name="GazeboSystem" type="system">
  <hardware>
    <plugin>gazebo_ros2_control/GazeboSystem</plugin>
  </hardware>

  <joint name="frame_down_joint">

    <command_interface name="position">
      <param name="min">-5</param>
      <param name="max">5</param>
    </command_interface>

    <state_interface name="position">
      <param name="initial_value">0.0</param>
    </state_interface>

    <state_interface name="position"/>
    <state_interface name="position"/>
  </joint>

  <joint name="frame_middle_joint">

    <command_interface name="position">
      <param name="min">-5</param>
      <param name="max">5</param>
    </command_interface>

    <state_interface name="position">
      <param name="initial_value">0.0</param>
    </state_interface>

    <state_interface name="position"/>
    <state_interface name="position"/>
  </joint>

  <joint name="finger_joint">

    <command_interface name="position">
      <param name="min">0</param>
      <param name="max">3</param>
    </command_interface>

    <state_interface name="position">
      <param name="initial_value">0.0</param>
    </state_interface>

    <state_interface name="position"/>
    <state_interface name="position"/>
  </joint>
</ros2_control>

<gazebo>
  <plugin filename="libgazebo_ros2_control.so" name="gazebo_ros2_control">
    <parameters>/home/yusuf/assignment_ws/robotics_software_engineer/module_5_assignment/config/position_controller.yaml</parameters>
  </plugin>
</gazebo>


</robot>
